<?xml version="1.0"?>
<robot name="saltbot" xmlns:xacro="http://ros.org/wiki/xacro">

    <xacro:include filename="/home/seniorproject/nvi_ws/install/salt_pkg/share/salt_pkg/urdf/gazebo_ref.xacro" />
    <xacro:include filename="/home/seniorproject/nvi_ws/install/salt_pkg/share/salt_pkg/urdf/gazebo_control.xacro" />
    <xacro:include filename="/home/seniorproject/nvi_ws/install/salt_pkg/share/salt_pkg/urdf/materials.xacro" />
    
    <xacro:property name="base_length" value=".762"/>
    <xacro:property name="base_width" value=".5334"/>
    <xacro:property name="base_height" value=".2"/>

    <xacro:property name="wheel_radius" value=".11"/>
    <xacro:property name="secondary_wheel_radius" value=".108"/>
    <xacro:property name="wheel_width" value=".04"/>

    <link name="base_footprint"/>

    <joint name="base_joint" type="fixed">
        <parent link="base_footprint"/>
        <child link="base_link" />
        <origin xyz="0 0 0" rpy="0 0 0"/>
    </joint>

    <link name="base_link">
        <visual>
            <origin xyz="0 0 .21" rpy="0 0 0"/>
            <geometry>
                <box size="${base_length} ${base_width} ${base_height}"/>
            </geometry>
            <material name="grey"/>
        </visual>

        <collision>
            <origin xyz="0 0 0.21" rpy="0 0 0"/>
            <geometry>
                <box size="${base_length} ${base_width} ${base_height}"/>
            </geometry>
        </collision>

        <xacro:box_inertia m="15" w="${base_width}" d="${base_length}" h="${base_height}"/>

    </link>

    <joint name="left_wheel_joint" type="continuous">
        <parent link="base_link"/>
        <child link="left_wheel_link"/>
        <origin xyz="0 0.271 .1" rpy="-1.57 0 0"/>
        <axis xyz="0 0 1"/>
    </joint>

    <link name="left_wheel_link">
        <visual>
            <origin xyz="0 0 0" rpy="0 0 1.57"/>
            <geometry>
                <cylinder radius="${wheel_radius}" length="${wheel_width}"/>
            </geometry>
            <material name="red"/>
        </visual>

        <collision>
            <origin xyz="0 0 0" rpy="0 0 1.57"/>
            <geometry>
                <cylinder radius="${wheel_radius}" length="${wheel_width}"/>
            </geometry>
        </collision>

        <xacro:cylinder_inertia m="0.5" r="${wheel_radius}" h="${wheel_width}"/>

    </link>

    <joint name="right_wheel_joint" type="continuous">
        <parent link="base_link"/>
        <child link="right_wheel_link"/>
        <origin xyz="0 -0.271 .1" rpy="-1.57 0 0"/>
        <axis xyz="0 0 1"/>
    </joint>

    <link name="right_wheel_link">
        <visual>
            <origin xyz="0 0 0" rpy="0 0 1.57"/>
            <geometry>
                <cylinder radius="${wheel_radius}" length="${wheel_width}"/>
            </geometry>
            <material name="red"/>
        </visual>

        <collision>
            <origin xyz="0 0 0" rpy="0 0 1.57"/>
            <geometry>
                <cylinder radius="${wheel_radius}" length="${wheel_width}"/>
            </geometry>
        </collision>

        <xacro:cylinder_inertia m="0.5" r="${wheel_radius}" h="${wheel_width}"/>

    </link>

    <joint name="BRwheel_joint" type="continuous">
        <parent link="base_link"/>
        <child link="BRwheel_link"/>
        <origin xyz="-.2667 -0.271 .103" rpy="-1.57 0 0"/>
        <axis xyz="0 0 1"/>
    </joint>

    <link name="BRwheel_link">
        <visual>
            <origin xyz="0 0 0" rpy="0 0 1.57"/>
            <geometry>
                <cylinder radius="${secondary_wheel_radius}" length="${wheel_width}"/>
            </geometry>
            <material name="red"/>
        </visual>

        <collision>
            <origin xyz="0 0 0" rpy="0 0 1.57"/>
            <geometry>
                <cylinder length="0.04" radius="0.11"/>
            </geometry>
        </collision>

        <xacro:cylinder_inertia m="0.5" r="${secondary_wheel_radius}" h="${wheel_width}"/>

    </link>

    <joint name="FRwheel_joint" type="continuous">
        <parent link="base_link"/>
        <child link="FRwheel_link"/>
        <origin xyz=".2667 -0.271 .103" rpy="-1.57 0 0"/>
        <axis xyz="0 0 1"/>
    </joint>

    <link name="FRwheel_link">
        <visual>
            <origin xyz="0 0 0" rpy="0 0 1.57"/>
            <geometry>
                <cylinder radius="${secondary_wheel_radius}" length="${wheel_width}"/>
            </geometry>
            <material name="green"/>
        </visual>

        <collision>
            <origin xyz="0 0 0" rpy="0 0 1.57"/>
            <geometry>
                <cylinder length="0.04" radius="0.11"/>
            </geometry>
        </collision>

        <xacro:cylinder_inertia m="0.5" r="${secondary_wheel_radius}" h="${wheel_width}"/>
        
    </link>

    <joint name="BLwheel_joint" type="continuous">
        <parent link="base_link"/>
        <child link="BLwheel_link"/>
        <origin xyz="-.2667 0.271 .103" rpy="-1.57 0 0"/>
        <axis xyz="0 0 1"/>
    </joint>

    <link name="BLwheel_link">
        <visual>
            <origin xyz="0 0 0" rpy="0 0 1.57"/>
            <geometry>
                <cylinder radius="${secondary_wheel_radius}" length="${wheel_width}"/>
            </geometry>
            <material name="orange"/>
        </visual>

        <collision>
            <origin xyz="0 0 0" rpy="0 0 1.57"/>
            <geometry>
                <cylinder length="0.04" radius="0.11"/>
            </geometry>
        </collision>

        <xacro:cylinder_inertia m="0.5" r="${secondary_wheel_radius}" h="${wheel_width}"/>

    </link>

    <joint name="FLwheel_joint" type="continuous">
        <parent link="base_link"/>
        <child link="FLwheel_link"/>
        <origin xyz=".2667 0.271 .103" rpy="-1.57 0 0"/>
        <axis xyz="0 0 1"/>
    </joint>

    <link name="FLwheel_link">
        <visual>
            <origin xyz="0 0 0" rpy="0 0 1.57"/>
            <geometry>
                <cylinder radius="${secondary_wheel_radius}" length="${wheel_width}"/>
            </geometry>
            <material name="blue"/>
        </visual>

        <collision>
            <origin xyz="0 0 0" rpy="0 0 1.57"/>
            <geometry>
                <cylinder length="0.04" radius="0.11"/>
            </geometry>
        </collision>

        <xacro:cylinder_inertia m="0.5" r="${secondary_wheel_radius}" h="${wheel_width}"/>

    </link>

    <joint name="imu_joint" type="fixed">
        <parent link="base_link"/>
        <child link="imu_link"/>
        <origin xyz=".3 0 .325"/>
    </joint>

    <link name="imu_link">
        <visual>
            <geometry>
                <box size="0.1 0.1 0.05"/>
            </geometry>
        </visual>

        <collision>
            <geometry>
                <box size="0.1 0.1 0.05"/>
            </geometry>
        </collision>

        <xacro:box_inertia m="0.1" w="0.1" d="0.1" h="0.1"/>

    </link>

    <link name="camera_link">
        <visual>
            <origin xyz="0 0 0" rpy="0 0 0"/>
            <geometry>
                <box size="0.015 0.015 0.5"/>
            </geometry>
        </visual>

        <collision>
            <origin xyz="0 0 0" rpy="0 0 0"/>
            <geometry>
                <box size="0.015 0.130 0.022"/>
            </geometry>
        </collision>

        <inertial>
            <origin xyz="0 0 0" rpy="0 0 0"/>
            <mass value="0.035"/>
            <inertia ixx="0.001"  ixy="0"  ixz="0" iyy="0.001" iyz="0" izz="0.001" />
        </inertial>
    </link>

    <joint name="camera_joint" type="fixed">
        <parent link="base_link"/>
        <child link="camera_link"/>
        <origin xyz=".3 0 .325"/>
    </joint>

    <link name="camera_depth_frame"/>

    <joint name="camera_depth_joint" type="fixed">
        <origin xyz="0 0 0" rpy="${-pi/2} 0 ${-pi/2}"/>
        <parent link="camera_link"/>
        <child link="camera_depth_frame"/>
    </joint>

    
    

</robot>
