<?xml version="1.0" ?>
<!-- =================================================================================== -->
<!-- |    This document was autogenerated by xacro from /home/seniorproject/nvi_ws/install/salt_pkg/share/salt_pkg/urdf/robot_model.xacro | -->
<!-- |    EDITING THIS FILE BY HAND IS NOT RECOMMENDED                                 | -->
<!-- =================================================================================== -->
<robot name="saltbot">
  <!--
    <xacro:include filename="/home/seniorproject/nvi_ws/install/salt_pkg/share/salt_pkg/urdf/gazebo_ref.xacro" />
    <xacro:include filename="/home/seniorproject/nvi_ws/install/salt_pkg/share/salt_pkg/urdf/gazebo_control.xacro" />
    -->
  <material name="grey">
    <color rgba="0.2 0.2 0.2 1"/>
  </material>
  <material name="white">
    <color rgba="1 1 1 1"/>
  </material>
  <material name="orange">
    <color rgba="1 0.3 0.1 1"/>
  </material>
  <material name="blue">
    <color rgba="0 0 1 1"/>
  </material>
  <material name="red">
    <color rgba="1 0 0 1"/>
  </material>
  <material name="green">
    <color rgba="0 1 0 1"/>
  </material>
  <material name="zed_mat">
    <color rgba="0.8 0.8 0.8 1.0"/>
  </material>
  <material name="zedm_mat">
    <color rgba="0 0 0 1.0"/>
  </material>
  <material name="zed2_mat">
    <color rgba="0.25 0.25 0.25 1.0"/>
  </material>
  <material name="zed2i_mat">
    <color rgba="0.25 0.25 0.25 1.0"/>
  </material>
  <material name="zedx_mat">
    <color rgba="0.25 0.25 0.25 1.0"/>
  </material>
  <material name="zedxm_mat">
    <color rgba="0.25 0.25 0.25 1.0"/>
  </material>
  <material name="virtual_mat">
    <color rgba="0.25 0.25 0.25 1.0"/>
  </material>
  <!-- Camera mounting point (the threaded screw hole in the bottom) -->
  <link name="zedm_camera_link"> </link>
  <!-- Camera Center -->
  <link name="zedm_camera_center">
    <visual>
      <origin rpy="0 0 0" xyz="0.0 0 0.0"/>
      <geometry>
        <mesh filename="package://zed_interfaces/meshes/zedm.stl"/>
      </geometry>
      <material name="zedm_mat"/>
    </visual>
    <collision>
      <origin rpy="0 0 0" xyz="0.0 0 0.0"/>
      <geometry>
        <mesh filename="package://zed_interfaces/meshes/zedm.stl"/>
      </geometry>
    </collision>
  </link>
  <joint name="zedm_camera_center_joint" type="fixed">
    <parent link="zedm_camera_link"/>
    <child link="zedm_camera_center"/>
    <origin rpy="0 0.0 0" xyz="0 0 0.01325"/>
  </joint>
  <!-- Left Camera -->
  <link name="zedm_left_camera_frame"> </link>
  <joint name="zedm_left_camera_joint" type="fixed">
    <parent link="zedm_camera_center"/>
    <child link="zedm_left_camera_frame"/>
    <origin rpy="0 0 0" xyz="0.0 0.03 0"/>
  </joint>
  <link name="zedm_left_camera_optical_frame"> </link>
  <joint name="zedm_left_camera_optical_joint" type="fixed">
    <origin rpy="-1.5707963267948966 0.0 -1.5707963267948966" xyz="0 0 0"/>
    <parent link="zedm_left_camera_frame"/>
    <child link="zedm_left_camera_optical_frame"/>
  </joint>
  <!-- Right Camera -->
  <link name="zedm_right_camera_frame"> </link>
  <joint name="zedm_right_camera_joint" type="fixed">
    <parent link="zedm_camera_center"/>
    <child link="zedm_right_camera_frame"/>
    <origin rpy="0 0 0" xyz="0.0 -0.03 0"/>
  </joint>
  <link name="zedm_right_camera_optical_frame"> </link>
  <joint name="zedm_right_camera_optical_joint" type="fixed">
    <origin rpy="-1.5707963267948966 0.0 -1.5707963267948966" xyz="0 0 0"/>
    <parent link="zedm_right_camera_frame"/>
    <child link="zedm_right_camera_optical_frame"/>
  </joint>
  <link name="base_footprint"/>
  <joint name="base_joint" type="fixed">
    <parent link="base_footprint"/>
    <child link="base_link"/>
    <origin rpy="0 0 0" xyz="0 0 0"/>
  </joint>
  <link name="base_link">
    <visual>
      <origin rpy="0 0 0" xyz="0 0 .21"/>
      <geometry>
        <box size="0.762 0.5334 0.2"/>
      </geometry>
      <material name="grey"/>
    </visual>
    <collision>
      <origin rpy="0 0 0" xyz="0 0 0.21"/>
      <geometry>
        <box size="0.762 0.5334 0.2"/>
      </geometry>
    </collision>
    <!--<xacro:box_inertia m="15" w="${base_width}" d="${base_length}" h="${base_height}"/>-->
  </link>
  <joint name="left_wheel_joint" type="continuous">
    <parent link="base_link"/>
    <child link="left_wheel_link"/>
    <origin rpy="-1.57 0 0" xyz="0 0.271 .1"/>
    <axis xyz="0 0 1"/>
  </joint>
  <link name="left_wheel_link">
    <visual>
      <origin rpy="0 0 1.57" xyz="0 0 0"/>
      <geometry>
        <cylinder length="0.04" radius="0.11"/>
      </geometry>
      <material name="red"/>
    </visual>
    <collision>
      <origin rpy="0 0 1.57" xyz="0 0 0"/>
      <geometry>
        <cylinder length="0.04" radius="0.11"/>
      </geometry>
    </collision>
    <!--<xacro:cylinder_inertia m="0.5" r="${wheel_radius}" h="${wheel_width}"/>-->
  </link>
  <joint name="right_wheel_joint" type="continuous">
    <parent link="base_link"/>
    <child link="right_wheel_link"/>
    <origin rpy="-1.57 0 0" xyz="0 -0.271 .1"/>
    <axis xyz="0 0 1"/>
  </joint>
  <link name="right_wheel_link">
    <visual>
      <origin rpy="0 0 1.57" xyz="0 0 0"/>
      <geometry>
        <cylinder length="0.04" radius="0.11"/>
      </geometry>
      <material name="red"/>
    </visual>
    <collision>
      <origin rpy="0 0 1.57" xyz="0 0 0"/>
      <geometry>
        <cylinder length="0.04" radius="0.11"/>
      </geometry>
    </collision>
    <!--<xacro:cylinder_inertia m="0.5" r="${wheel_radius}" h="${wheel_width}"/>-->
  </link>
  <joint name="BRwheel_joint" type="continuous">
    <parent link="base_link"/>
    <child link="BRwheel_link"/>
    <origin rpy="-1.57 0 0" xyz="-.2667 -0.271 .103"/>
    <axis xyz="0 0 1"/>
  </joint>
  <link name="BRwheel_link">
    <visual>
      <origin rpy="0 0 1.57" xyz="0 0 0"/>
      <geometry>
        <cylinder length="0.04" radius="0.108"/>
      </geometry>
      <material name="red"/>
    </visual>
    <collision>
      <origin rpy="0 0 1.57" xyz="0 0 0"/>
      <geometry>
        <cylinder length="0.04" radius="0.11"/>
      </geometry>
    </collision>
    <!--<xacro:cylinder_inertia m="0.5" r="${secondary_wheel_radius}" h="${wheel_width}"/>-->
  </link>
  <joint name="FRwheel_joint" type="continuous">
    <parent link="base_link"/>
    <child link="FRwheel_link"/>
    <origin rpy="-1.57 0 0" xyz=".2667 -0.271 .103"/>
    <axis xyz="0 0 1"/>
  </joint>
  <link name="FRwheel_link">
    <visual>
      <origin rpy="0 0 1.57" xyz="0 0 0"/>
      <geometry>
        <cylinder length="0.04" radius="0.108"/>
      </geometry>
      <material name="green"/>
    </visual>
    <collision>
      <origin rpy="0 0 1.57" xyz="0 0 0"/>
      <geometry>
        <cylinder length="0.04" radius="0.11"/>
      </geometry>
    </collision>
    <!--<xacro:cylinder_inertia m="0.5" r="${secondary_wheel_radius}" h="${wheel_width}"/>-->
  </link>
  <joint name="BLwheel_joint" type="continuous">
    <parent link="base_link"/>
    <child link="BLwheel_link"/>
    <origin rpy="-1.57 0 0" xyz="-.2667 0.271 .103"/>
    <axis xyz="0 0 1"/>
  </joint>
  <link name="BLwheel_link">
    <visual>
      <origin rpy="0 0 1.57" xyz="0 0 0"/>
      <geometry>
        <cylinder length="0.04" radius="0.108"/>
      </geometry>
      <material name="orange"/>
    </visual>
    <collision>
      <origin rpy="0 0 1.57" xyz="0 0 0"/>
      <geometry>
        <cylinder length="0.04" radius="0.11"/>
      </geometry>
    </collision>
    <!--<xacro:cylinder_inertia m="0.5" r="${secondary_wheel_radius}" h="${wheel_width}"/>-->
  </link>
  <joint name="FLwheel_joint" type="continuous">
    <parent link="base_link"/>
    <child link="FLwheel_link"/>
    <origin rpy="-1.57 0 0" xyz=".2667 0.271 .103"/>
    <axis xyz="0 0 1"/>
  </joint>
  <link name="FLwheel_link">
    <visual>
      <origin rpy="0 0 1.57" xyz="0 0 0"/>
      <geometry>
        <cylinder length="0.04" radius="0.108"/>
      </geometry>
      <material name="blue"/>
    </visual>
    <collision>
      <origin rpy="0 0 1.57" xyz="0 0 0"/>
      <geometry>
        <cylinder length="0.04" radius="0.11"/>
      </geometry>
    </collision>
    <!--<xacro:cylinder_inertia m="0.5" r="${secondary_wheel_radius}" h="${wheel_width}"/>-->
  </link>
  <joint name="imu_joint" type="fixed">
    <parent link="base_link"/>
    <child link="imu_link"/>
    <origin xyz=".3 0 .325"/>
  </joint>
  <link name="imu_link">
    <visual>
      <geometry>
        <box size="0.1 0.1 0.05"/>
      </geometry>
    </visual>
    <collision>
      <geometry>
        <box size="0.1 0.1 0.05"/>
      </geometry>
    </collision>
    <!--<xacro:box_inertia m="0.1" w="0.1" d="0.1" h="0.1"/>-->
  </link>
  <!-- ZED Localization -> The reference link is '$(arg camera_name)_camera_link' and 'base_link' is a child -->
  <joint name="zedm_joint" type="fixed">
    <parent link="base_link"/>
    <child link="zedm_camera_link"/>
    <origin rpy="0 0 0" xyz="-0.12 0.0 -0.25"/>
  </joint>
</robot>
